Workbook

Sheet Read me
A1: Ask Hava hand-run test tracker
A2: Goes with docs/pilot/hand-run-test.md (the playbook). Import into Google Sheets: Drive > New > File upload, then Open with Google Sheets.
A4: How the colors work
A5: Blue text = you type it. Black text = a formula; don't type over it. Yellow cells on Settings = set these before the test.
A6: Every data tab has formulas filled down 300 rows, so you only ever type in the blue columns.
A8: It's loaded with FAKE test data
A9: Every business, homeowner, quote and payment in here is made up (Test Pool Co, Test Homeowner, example.com). Use it for the dry run (docs/pilot/dry-run.md), then clear it:
A10: To clear: on Businesses, Requests, Quotes, Picks, Nudges and Posts, select the blue columns from row 2 down and press Delete. On Weekly, clear the blue minutes columns. Formulas stay.
A12: Tabs
A13: Settings: test start date, your one or two pushed trades, the week the paid weeks start.
A14: Rules: the test's definitions, fixed before it starts (playbook section 3).
A15: Businesses: one row per business that signs up. Copy from the sign-up form's responses.
... A25: This sheet holds homeowners' first names, addresses and emails once the real test starts. Share it with nobody. Never paste rows into an AI tool. Delete those columns 90 days after the test ends.

Sheet Settings
A1: Setting | B1: Value
A2: Test start date (Monday of week 1) | B2: 46328
A3: Pushed trade 1 (category id from the trade list) | B3: pool_cleaning
A4: Pushed trade 2 (leave blank if only one) | B4: handyman
A5: First paid week | B5: 4
A7: The pushed trades are set at the start of week 1 and kept for the whole test (playbook section 7). The sample values are placeholders until Grok's trade research is in.

Sheet Rules
A1: Term | B1: Meaning (fixed before the test starts; playbook section 3)
A2: Request | B2: One real job, from one household, in Lake Havasu City. A second job from the same household counts separately; the same job sent twice counts once. Tests, jokes and out-of-town jobs don't count.
A3: Source class | B3: Seeded (someone you asked, or who knows you), Partner (a property manager, rental host or realtor you lined up), or Organic (found Ask Hava on their own). When unsure, it's Seeded.
A4: Routable | B4: In a trade with at least one active business whose license covers the job.
A5: Pushed trade | B5: One of the one or two trades on Settings, fixed at the start of week 1.
A6: Valid quote | B6: A price (fixed, range, or visit fee) and when they could do it, received within 24 hours of the card being sent.
A7: Quote clock | B7: Starts when you send the card email; ends 24 hours later.
A8: Active business | B8: Has sent at least one quote. A sign-up alone doesn't count.
A9: No pick | B9: No pick 3 days after the last quote window ends. Ask her once why, then close it.
A10: Nudge | B10: Anything beyond the standard emails: a reminder, a personal message, a visit. Log every one on Nudges.
A11: Season | B11: Every weekly row carries its dates. Report the result as a winter test.
A12: Changes | B12: If something comes up these rules don't cover: decide it, write it below with the date, apply it to every later case.

Sheet Businesses
A1: Business ID | B1: Business name | C1: Email | D1: Main trade (category id) | E1: Other trades | F1: License (ROC class, or none) | G1: ROC checked active (Y/N) | H1: Sign-up date | I1: How they heard | J1: Signed up on their own (Y/N) | K1: Quotes sent | L1: Active (has quoted) | M1: Wins | N1: Quotes per win | O1: Paid introductions | Q1: FAKE TEST DATA in every row. Clear before the real test (Read me).
A2: B01 | B2: Test Pool Co A | C2: b01@example.com | D2: pool_cleaning | F2: none | G2: N/A | H2: 46338 | I2: Facebook group: oo | J2: Y | K2: =IF(A2="","",COUNTIF(Quotes!$C$2:$C$301,A2)) -> 2 | L2: =IF(A2="","",K2>0) -> TRUE | M2: =IF(A2="","",COUNTIF(Picks!$C$2:$C$301,A2)) -> 0 | N2: =IF(A2="","",IF(M2=0,"no wins",K2/M2)) -> no wins | O2: =IF(A2="","",COUNTIFS(Picks!$C$2:$C$301,A2,Picks!$H$2:$H$301,"Y")) -> 0
A3: B02 | B3: Test Pool Co B | C3: b02@example.com | D3: pool_cleaning | E3: pool_repair | F3: KA-6 | G3: Y | H3: 46332 | I3: Facebook group: cp | J3: Y | K3: =IF(A3="","",COUNTIF(Quotes!$C$2:$C$301,A3)) -> 3 | L3: =IF(A3="","",K3>0) -> TRUE | M3: =IF(A3="","",COUNTIF(Picks!$C$2:$C$301,A3)) -> 0 | N3: =IF(A3="","",IF(M3=0,"no wins",K3/M3)) -> no wins | O3: =IF(A3="","",COUNTIFS(Picks!$C$2:$C$301,A3,Picks!$H$2:$H$301,"Y")) -> 0
A4: B03 | B4: Test Pool Co C | C4: b03@example.com | D4: pool_cleaning | F4: none | G4: N/A | H4: 46340 | I4: Another business | J4: Y | K4: =IF(A4="","",COUNTIF(Quotes!$C$2:$C$301,A4)) -> 4 | L4: =IF(A4="","",K4>0) -> TRUE | M4: =IF(A4="","",COUNTIF(Picks!$C$2:$C$301,A4)) -> 0 | N4: =IF(A4="","",IF(M4=0,"no wins",K4/M4)) -> no wins | O4: =IF(A4="","",COUNTIFS(Picks!$C$2:$C$301,A4,Picks!$H$2:$H$301,"Y")) -> 0
A5: B04 | B5: Test Pool Co D | C5: b04@example.com | D5: pool_cleaning | F5: none | G5: N/A | H5: 46329 | I5: Met Casey | J5: N | K5: =IF(A5="","",COUNTIF(Quotes!$C$2:$C$301,A5)) -> 4 | L5: =IF(A5="","",K5>0) -> TRUE | M5: =IF(A5="","",COUNTIF(Picks!$C$2:$C$301,A5)) -> 0 | N5: =IF(A5="","",IF(M5=0,"no wins",K5/M5)) -> no wins | O5: =IF(A5="","",COUNTIFS(Picks!$C$2:$C$301,A5,Picks!$H$2:$H$301,"Y")) -> 0
A6: B05 | B6: Test Pool Co E | C6: b05@example.com | D6: pool_cleaning | F6: none | G6: N/A | H6: 46330 | I6: Facebook group: oo | J6: Y | K6: =IF(A6="","",COUNTIF(Quotes!$C$2:$C$301,A6)) -> 6 | L6: =IF(A6="","",K6>0) -> TRUE | M6: =IF(A6="","",COUNTIF(Picks!$C$2:$C$301,A6)) -> 3 | N6: =IF(A6="","",IF(M6=0,"no wins",K6/M6)) -> 2 | O6: =IF(A6="","",COUNTIFS(Picks!$C$2:$C$301,A6,Picks!$H$2:$H$301,"Y")) -> 2
A7: B06 | B7: Test Handyman A | C7: b06@example.com | D7: handyman | F7: none | G7: N/A | H7: 46331 | I7: Facebook group: cp | J7: Y | K7: =IF(A7="","",COUNTIF(Quotes!$C$2:$C$301,A7)) -> 4 | L7: =IF(A7="","",K7>0) -> TRUE | M7: =IF(A7="","",COUNTIF(Picks!$C$2:$C$301,A7)) -> 0 | N7: =IF(A7="","",IF(M7=0,"no wins",K7/M7)) -> no wins | O7: =IF(A7="","",COUNTIFS(Picks!$C$2:$C$301,A7,Picks!$H$2:$H$301,"Y")) -> 0
A8: B07 | B8: Test Handyman B | C8: b07@example.com | D8: handyman | E8: painting | F8: none | G8: N/A | H8: 46339 | I8: Facebook group: oo | J8: Y | K8: =IF(A8="","",COUNTIF(Quotes!$C$2:$C$301,A8)) -> 5 | L8: =IF(A8="","",K8>0) -> TRUE | M8: =IF(A8="","",COUNTIF(Picks!$C$2:$C$301,A8)) -> 3 | N8: =IF(A8="","",IF(M8=0,"no wins",K8/M8)) -> 1.6666667 | O8: =IF(A8="","",COUNTIFS(Picks!$C$2:$C$301,A8,Picks!$H$2:$H$301,"Y")) -> 2
A9: B08 | B9: Test Handyman C | C9: b08@example.com | D9: handyman | F9: none | G9: N/A | H9: 46329 | I9: Met Casey | J9: N | K9: =IF(A9="","",COUNTIF(Quotes!$C$2:$C$301,A9)) -> 3 | L9: =IF(A9="","",K9>0) -> TRUE | M9: =IF(A9="","",COUNTIF(Picks!$C$2:$C$301,A9)) -> 0 | N9: =IF(A9="","",IF(M9=0,"no wins",K9/M9)) -> no wins | O9: =IF(A9="","",COUNTIFS(Picks!$C$2:$C$301,A9,Picks!$H$2:$H$301,"Y")) -> 0
A10: B09 | B10: Test Handyman D | C10: b09@example.com | D10: handyman | F10: none | G10: N/A | H10: 46344 | I10: Facebook group: cp | J10: Y | K10: =IF(A10="","",COUNTIF(Quotes!$C$2:$C$301,A10)) -> 6 | L10: =IF(A10="","",K10>0) -> TRUE | M10: =IF(A10="","",COUNTIF(Picks!$C$2:$C$301,A10)) -> 1 | N10: =IF(A10="","",IF(M10=0,"no wins",K10/M10)) -> 6 | O10: =IF(A10="","",COUNTIFS(Picks!$C$2:$C$301,A10,Picks!$H$2:$H$301,"Y")) -> 0
A11: B10 | B11: Test Handyman E | C11: b10@example.com | D11: handyman | F11: none | G11: N/A | H11: 46334 | I11: Friend | J11: Y | K11: =IF(A11="","",COUNTIF(Quotes!$C$2:$C$301,A11)) -> 8 | L11: =IF(A11="","",K11>0) -> TRUE | M11: =IF(A11="","",COUNTIF(Picks!$C$2:$C$301,A11)) -> 1 | N11: =IF(A11="","",IF(M11=0,"no wins",K11/M11)) -> 8 | O11: =IF(A11="","",COUNTIFS(Picks!$C$2:$C$301,A11,Picks!$H$2:$H$301,"Y")) -> 1
A12: B11 | B12: Test HVAC Co | C12: b11@example.com | D12: hvac_repair | F12: R-39 | G12: Y | H12: 46329 | I12: Facebook group: oo | J12: Y | K12: =IF(A12="","",COUNTIF(Quotes!$C$2:$C$301,A12)) -> 1 | L12: =IF(A12="","",K12>0) -> TRUE | M12: =IF(A12="","",COUNTIF(Picks!$C$2:$C$301,A12)) -> 1 | N12: =IF(A12="","",IF(M12=0,"no wins",K12/M12)) -> 1 | O12: =IF(A12="","",COUNTIFS(Picks!$C$2:$C$301,A12,Picks!$H$2:$H$301,"Y")) -> 0
A13: B12 | B13: Test Cleaning Co | C13: b12@example.com | D13: house_cleaning | F13: none | G13: N/A | H13: 46330 | I13: Facebook group: cp | J13: Y | K13: =IF(A13="","",COUNTIF(Quotes!$C$2:$C$301,A13)) -> 0 | L13: =IF(A13="","",K13>0) -> FALSE | M13: =IF(A13="","",COUNTIF(Picks!$C$2:$C$301,A13)) -> 0 | N13: =IF(A13="","",IF(M13=0,"no wins",K13/M13)) -> no wins | O13: =IF(A13="","",COUNTIFS(Picks!$C$2:$C$301,A13,Picks!$H$2:$H$301,"Y")) -> 0
A14: B13 | B14: Test Handyman F | C14: b13@example.com | D14: handyman | F14: none | G14: N/A | H14: 46341 | I14: Facebook group: oo | J14: Y | K14: =IF(A14="","",COUNTIF(Quotes!$C$2:$C$301,A14)) -> 0 | L14: =IF(A14="","",K14>0) -> FALSE | M14: =IF(A14="","",COUNTIF(Picks!$C$2:$C$301,A14)) -> 0 | N14: =IF(A14="","",IF(M14=0,"no wins",K14/M14)) -> no wins | O14: =IF(A14="","",COUNTIFS(Picks!$C$2:$C$301,A14,Picks!$H$2:$H$301,"Y")) -> 0
K15: =IF(A15="","",COUNTIF(Quotes!$C$2:$C$301,A15)) | L15: =IF(A15="","",K15>0) | M15: =IF(A15="","",COUNTIF(Picks!$C$2:$C$301,A15)) | N15: =IF(A15="","",IF(M15=0,"no wins",K15/M15)) | O15: =IF(A15="","",COUNTIFS(Picks!$C$2:$C$301,A15,Picks!$H$2:$H$301,"Y"))
K16: =IF(A16="","",COUNTIF(Quotes!$C$2:$C$301,A16)) | L16: =IF(A16="","",K16>0) | M16: =IF(A16="","",COUNTIF(Picks!$C$2:$C$301,A16)) | N16: =IF(A16="","",IF(M16=0,"no wins",K16/M16)) | O16: =IF(A16="","",COUNTIFS(Picks!$C$2:$C$301,A16,Picks!$H$2:$H$301,"Y"))
K17: =IF(A17="","",COUNTIF(Quotes!$C$2:$C$301,A17)) | L17: =IF(A17="","",K17>0) | M17: =IF(A17="","",COUNTIF(Picks!$C$2:$C$301,A17)) | N17: =IF(A17="","",IF(M17=0,"no wins",K17/M17)) | O17: =IF(A17="","",COUNTIFS(Picks!$C$2:$C$301,A17,Picks!$H$2:$H$301,"Y"))
K18: =IF(A18="","",COUNTIF(Quotes!$C$2:$C$301,A18)) | L18: =IF(A18="","",K18>0) | M18: =IF(A18="","",COUNTIF(Picks!$C$2:$C$301,A18)) | N18: =IF(A18="","",IF(M18=0,"no wins",K18/M18)) | O18: =IF(A18="","",COUNTIFS(Picks!$C$2:$C$301,A18,Picks!$H$2:$H$301,"Y"))
K19: =IF(A19="","",COUNTIF(Quotes!$C$2:$C$301,A19)) | L19: =IF(A19="","",K19>0) | M19: =IF(A19="","",COUNTIF(Picks!$C$2:$C$301,A19)) | N19: =IF(A19="","",IF(M19=0,"no wins",K19/M19)) | O19: =IF(A19="","",COUNTIFS(Picks!$C$2:$C$301,A19,Picks!$H$2:$H$301,"Y"))
K20: =IF(A20="","",COUNTIF(Quotes!$C$2:$C$301,A20)) | L20: =IF(A20="","",K20>0) | M20: =IF(A20="","",COUNTIF(Picks!$C$2:$C$301,A20)) | N20: =IF(A20="","",IF(M20=0,"no wins",K20/M20)) | O20: =IF(A20="","",COUNTIFS(Picks!$C$2:$C$301,A20,Picks!$H$2:$H$301,"Y"))
K21: =IF(A21="","",COUNTIF(Quotes!$C$2:$C$301,A21)) | L21: =IF(A21="","",K21>0) | M21: =IF(A21="","",COUNTIF(Picks!$C$2:$C$301,A21)) | N21: =IF(A21="","",IF(M21=0,"no wins",K21/M21)) | O21: =IF(A21="","",COUNTIFS(Picks!$C$2:$C$301,A21,Picks!$H$2:$H$301,"Y"))
K22: =IF(A22="","",COUNTIF(Quotes!$C$2:$C$301,A22)) | L22: =IF(A22="","",K22>0) | M22: =IF(A22="","",COUNTIF(Picks!$C$2:$C$301,A22)) | N22: =IF(A22="","",IF(M22=0,"no wins",K22/M22)) | O22: =IF(A22="","",COUNTIFS(Picks!$C$2:$C$301,A22,Picks!$H$2:$H$301,"Y"))
K23: =IF(A23="","",COUNTIF(Quotes!$C$2:$C$301,A23)) | L23: =IF(A23="","",K23>0) | M23: =IF(A23="","",COUNTIF(Picks!$C$2:$C$301,A23)) | N23: =IF(A23="","",IF(M23=0,"no wins",K23/M23)) | O23: =IF(A23="","",COUNTIFS(Picks!$C$2:$C$301,A23,Picks!$H$2:$H$301,"Y"))
K24: =IF(A24="","",COUNTIF(Quotes!$C$2:$C$301,A24)) | L24: =IF(A24="","",K24>0) | M24: =IF(A24="","",COUNTIF(Picks!$C$2:$C$301,A24)) | N24: =IF(A24="","",IF(M24=0,"no wins",K24/M24)) | O24: =IF(A24="","",COUNTIFS(Picks!$C$2:$C$301,A24,Picks!$H$2:$H$301,"Y"))
K25: =IF(A25="","",COUNTIF(Quotes!$C$2:$C$301,A25)) | L25: =IF(A25="","",K25>0) | M25: =IF(A25="","",COUNTIF(Picks!$C$2:$C$301,A25)) | N25: =IF(A25="","",IF(M25=0,"no wins",K25/M25)) | O25: =IF(A25="","",COUNTIFS(Picks!$C$2:$C$301,A25,Picks!$H$2:$H$301,"Y"))
K26: =IF(A26="","",COUNTIF(Quotes!$C$2:$C$301,A26)) | L26: =IF(A26="","",K26>0) | M26: =IF(A26="","",COUNTIF(Picks!$C$2:$C$301,A26)) | N26: =IF(A26="","",IF(M26=0,"no wins",K26/M26)) | O26: =IF(A26="","",COUNTIFS(Picks!$C$2:$C$301,A26,Picks!$H$2:$H$301,"Y"))
... K301: =IF(A301="","",COUNTIF(Quotes!$C$2:$C$301,A301)) | L301: =IF(A301="","",K301>0) | M301: =IF(A301="","",COUNTIF(Picks!$C$2:$C$301,A301)) | N301: =IF(A301="","",IF(M301=0,"no wins",K301/M301)) | O301: =IF(A301="","",COUNTIFS(Picks!$C$2:$C$301,A301,Picks!$H$2:$H$301,"Y"))

Sheet Requests
A1: Request ID | B1: Received | C1: Week | D1: Trade (category id) | E1: Pushed trade | F1: Source class | G1: Routable (Y/N) | H1: First name | I1: Job address | J1: Email | K1: Card sent | L1: Card corrected by homeowner (Y/N) | M1: Valid quotes in 24h | N1: Hours to first valid quote | O1: Pushed and routable | P1: First-quote hours (pushed and routable) | Q1: Picked | R1: Your minutes on this request | S1: No-pick reason | T1: Nudged | V1: FAKE TEST DATA in every row. Clear before the real test (Read me).
A2: R001 | B2: 46328.74 | C2: =IF(B2="","",INT((B2-Settings!$B$2)/7)+1) -> 1 | D2: handyman | E2: =IF(A2="","",OR(D2=Settings!$B$3,AND(Settings!$B$4<>"",D2=Settings!$B$4))) -> TRUE | F2: Partner | G2: Y | H2: Test Homeowner 01 | I2: 100 Test St, Lake Havasu City | J2: homeowner01@example.com | K2: 46328.781 | L2: N | M2: =IF(A2="","",COUNTIFS(Quotes!$B$2:$B$301,A2,Quotes!$G$2:$G$301,"Y")) -> 2 | N2: =IF(A2="","",IF(M2=0,"",_xlfn.MINIFS(Quotes!$F$2:$F$301,Quotes!$B$2:$B$301,A2,Quotes!$G$2:$G$301,"Y"))) -> 2.8895749 | O2: =IF(A2="","",AND(E2,G2="Y")) -> TRUE | P2: =IF(A2="","",IF(AND(O2,N2<>""),N2,"")) -> 2.8895749 | Q2: =IF(A2="","",COUNTIF(Picks!$A$2:$A$301,A2)>0) -> FALSE | R2: 25 | S2: No reply | T2: =IF(A2="","",COUNTIF(Nudges!$C$2:$C$301,A2)>0) -> FALSE
A3: R002 | B3: 46330.646 | C3: =IF(B3="","",INT((B3-Settings!$B$2)/7)+1) -> 1 | D3: pool_cleaning | E3: =IF(A3="","",OR(D3=Settings!$B$3,AND(Settings!$B$4<>"",D3=Settings!$B$4))) -> TRUE | F3: Seeded | G3: Y | H3: Test Homeowner 02 | I3: 101 Test St, Lake Havasu City | J3: homeowner02@example.com | K3: 46330.688 | L3: Y | M3: =IF(A3="","",COUNTIFS(Quotes!$B$2:$B$301,A3,Quotes!$G$2:$G$301,"Y")) -> 0 | N3: =IF(A3="","",IF(M3=0,"",_xlfn.MINIFS(Quotes!$F$2:$F$301,Quotes!$B$2:$B$301,A3,Quotes!$G$2:$G$301,"Y"))) | O3: =IF(A3="","",AND(E3,G3="Y")) -> TRUE | P3: =IF(A3="","",IF(AND(O3,N3<>""),N3,"")) | Q3: =IF(A3="","",COUNTIF(Picks!$A$2:$A$301,A3)>0) -> FALSE | R3: 30 | T3: =IF(A3="","",COUNTIF(Nudges!$C$2:$C$301,A3)>0) -> TRUE
A4: R003 | B4: 46331.427 | C4: =IF(B4="","",INT((B4-Settings!$B$2)/7)+1) -> 1 | D4: handyman | E4: =IF(A4="","",OR(D4=Settings!$B$3,AND(Settings!$B$4<>"",D4=Settings!$B$4))) -> TRUE | F4: Seeded | G4: Y | H4: Test Homeowner 03 | I4: 102 Test St, Lake Havasu City | J4: homeowner03@example.com | K4: 46331.51 | L4: Y | M4: =IF(A4="","",COUNTIFS(Quotes!$B$2:$B$301,A4,Quotes!$G$2:$G$301,"Y")) -> 2 | N4: =IF(A4="","",IF(M4=0,"",_xlfn.MINIFS(Quotes!$F$2:$F$301,Quotes!$B$2:$B$301,A4,Quotes!$G$2:$G$301,"Y"))) -> 7.3223721 | O4: =IF(A4="","",AND(E4,G4="Y")) -> TRUE | P4: =IF(A4="","",IF(AND(O4,N4<>""),N4,"")) -> 7.3223721 | Q4: =IF(A4="","",COUNTIF(Picks!$A$2:$A$301,A4)>0) -> FALSE | R4: 40 | S4: Prices too high | T4: =IF(A4="","",COUNTIF(Nudges!$C$2:$C$301,A4)>0) -> TRUE
A5: R004 | B5: 46331.698 | C5: =IF(B5="","",INT((B5-Settings!$B$2)/7)+1) -> 1 | D5: handyman | E5: =IF(A5="","",OR(D5=Settings!$B$3,AND(Settings!$B$4<>"",D5=Settings!$B$4))) -> TRUE | F5: Organic | G5: Y | H5: Test Homeowner 04 | I5: 103 Test St, Lake Havasu City | J5: homeowner04@example.com | K5: 46331.781 | L5: Y | M5: =IF(A5="","",COUNTIFS(Quotes!$B$2:$B$301,A5,Quotes!$G$2:$G$301,"Y")) -> 0 | N5: =IF(A5="","",IF(M5=0,"",_xlfn.MINIFS(Quotes!$F$2:$F$301,Quotes!$B$2:$B$301,A5,Quotes!$G$2:$G$301,"Y"))) | O5: =IF(A5="","",AND(E5,G5="Y")) -> TRUE | P5: =IF(A5="","",IF(AND(O5,N5<>""),N5,"")) | Q5: =IF(A5="","",COUNTIF(Picks!$A$2:$A$301,A5)>0) -> FALSE | R5: 35 | T5: =IF(A5="","",COUNTIF(Nudges!$C$2:$C$301,A5)>0) -> FALSE
A6: R005 | B6: 46334.385 | C6: =IF(B6="","",INT((B6-Settings!$B$2)/7)+1) -> 1 | D6: pool_cleaning | E6: =IF(A6="","",OR(D6=Settings!$B$3,AND(Settings!$B$4<>"",D6=Settings!$B$4))) -> TRUE | F6: Organic | G6: Y | H6: Test Homeowner 05 | I6: 104 Test St, Lake Havasu City | J6: homeowner05@example.com | K6: 46334.427 | L6: N | M6: =IF(A6="","",COUNTIFS(Quotes!$B$2:$B$301,A6,Quotes!$G$2:$G$301,"Y")) -> 1 | N6: =IF(A6="","",IF(M6=0,"",_xlfn.MINIFS(Quotes!$F$2:$F$301,Quotes!$B$2:$B$301,A6,Quotes!$G$2:$G$301,"Y"))) -> 0.68401461 | O6: =IF(A6="","",AND(E6,G6="Y")) -> TRUE | P6: =IF(A6="","",IF(AND(O6,N6<>""),N6,"")) -> 0.68401461 | Q6: =IF(A6="","",COUNTIF(Picks!$A$2:$A$301,A6)>0) -> FALSE | R6: 35 | S6: Prices too high | T6: =IF(A6="","",COUNTIF(Nudges!$C$2:$C$301,A6)>0) -> FALSE
A7: R006 | B7: 46335.604 | C7: =IF(B7="","",INT((B7-Settings!$B$2)/7)+1) -> 2 | D7: pool_cleaning | E7: =IF(A7="","",OR(D7=Settings!$B$3,AND(Settings!$B$4<>"",D7=Settings!$B$4))) -> TRUE | F7: Seeded | G7: Y | H7: Test Homeowner 06 | I7: 105 Test St, Lake Havasu City | J7: homeowner06@example.com | K7: 46335.688 | L7: N | M7: =IF(A7="","",COUNTIFS(Quotes!$B$2:$B$301,A7,Quotes!$G$2:$G$301,"Y")) -> 4 | N7: =IF(A7="","",IF(M7=0,"",_xlfn.MINIFS(Quotes!$F$2:$F$301,Quotes!$B$2:$B$301,A7,Quotes!$G$2:$G$301,"Y"))) -> 2.3489009 | O7: =IF(A7="","",AND(E7,G7="Y")) -> TRUE | P7: =IF(A7="","",IF(AND(O7,N7<>""),N7,"")) -> 2.3489009 | Q7: =IF(A7="","",COUNTIF(Picks!$A$2:$A$301,A7)>0) -> FALSE | R7: 20 | S7: No reply | T7: =IF(A7="","",COUNTIF(Nudges!$C$2:$C$301,A7)>0) -> FALSE
A8: R007 | B8: 46336.521 | C8: =IF(B8="","",INT((B8-Settings!$B$2)/7)+1) -> 2 | D8: pool_cleaning | E8: =IF(A8="","",OR(D8=Settings!$B$3,AND(Settings!$B$4<>"",D8=Settings!$B$4))) -> TRUE | F8: Organic | G8: Y | H8: Test Homeowner 07 | I8: 106 Test St, Lake Havasu City | J8: homeowner07@example.com | K8: 46336.604 | L8: N | M8: =IF(A8="","",COUNTIFS(Quotes!$B$2:$B$301,A8,Quotes!$G$2:$G$301,"Y")) -> 0 | N8: =IF(A8="","",IF(M8=0,"",_xlfn.MINIFS(Quotes!$F$2:$F$301,Quotes!$B$2:$B$301,A8,Quotes!$G$2:$G$301,"Y"))) | O8: =IF(A8="","",AND(E8,G8="Y")) -> TRUE | P8: =IF(A8="","",IF(AND(O8,N8<>""),N8,"")) | Q8: =IF(A8="","",COUNTIF(Picks!$A$2:$A$301,A8)>0) -> FALSE | R8: 30 | T8: =IF(A8="","",COUNTIF(Nudges!$C$2:$C$301,A8)>0) -> TRUE
A9: R008 | B9: 46336.677 | C9: =IF(B9="","",INT((B9-Settings!$B$2)/7)+1) -> 2 | D9: handyman | E9: =IF(A9="","",OR(D9=Settings!$B$3,AND(Settings!$B$4<>"",D9=Settings!$B$4))) -> TRUE | F9: Seeded | G9: Y | H9: Test Homeowner 08 | I9: 107 Test St, Lake Havasu City | J9: homeowner08@example.com | K9: 46336.76 | L9: N | M9: =IF(A9="","",COUNTIFS(Quotes!$B$2:$B$301,A9,Quotes!$G$2:$G$301,"Y")) -> 3 | N9: =IF(A9="","",IF(M9=0,"",_xlfn.MINIFS(Quotes!$F$2:$F$301,Quotes!$B$2:$B$301,A9,Quotes!$G$2:$G$301,"Y"))) -> 1.7040242 | O9: =IF(A9="","",AND(E9,G9="Y")) -> TRUE | P9: =IF(A9="","",IF(AND(O9,N9<>""),N9,"")) -> 1.7040242 | Q9: =IF(A9="","",COUNTIF(Picks!$A$2:$A$301,A9)>0) -> TRUE | R9: 35 | T9: =IF(A9="","",COUNTIF(Nudges!$C$2:$C$301,A9)>0) -> FALSE
A10: R009 | B10: 46338.375 | C10: =IF(B10="","",INT((B10-Settings!$B$2)/7)+1) -> 2 | D10: plumbing_repair | E10: =IF(A10="","",OR(D10=Settings!$B$3,AND(Settings!$B$4<>"",D10=Settings!$B$4))) -> FALSE | F10: Organic | G10: N | H10: Test Homeowner 09 | I10: 108 Test St, Lake Havasu City | J10: homeowner09@example.com | M10: =IF(A10="","",COUNTIFS(Quotes!$B$2:$B$301,A10,Quotes!$G$2:$G$301,"Y")) -> 0 | N10: =IF(A10="","",IF(M10=0,"",_xlfn.MINIFS(Quotes!$F$2:$F$301,Quotes!$B$2:$B$301,A10,Quotes!$G$2:$G$301,"Y"))) | O10: =IF(A10="","",AND(E10,G10="Y")) -> FALSE | P10: =IF(A10="","",IF(AND(O10,N10<>""),N10,"")) | Q10: =IF(A10="","",COUNTIF(Picks!$A$2:$A$301,A10)>0) -> FALSE | R10: 40 | S10: Not covered (template A) | T10: =IF(A10="","",COUNTIF(Nudges!$C$2:$C$301,A10)>0) -> FALSE
A11: R010 | B11: 46339.635 | C11: =IF(B11="","",INT((B11-Settings!$B$2)/7)+1) -> 2 | D11: house_cleaning | E11: =IF(A11="","",OR(D11=Settings!$B$3,AND(Settings!$B$4<>"",D11=Settings!$B$4))) -> FALSE | F11: Organic | G11: Y | H11: Test Homeowner 10 | I11: 109 Test St, Lake Havasu City | J11: homeowner10@example.com | K11: 46339.677 | L11: N | M11: =IF(A11="","",COUNTIFS(Quotes!$B$2:$B$301,A11,Quotes!$G$2:$G$301,"Y")) -> 0 | N11: =IF(A11="","",IF(M11=0,"",_xlfn.MINIFS(Quotes!$F$2:$F$301,Quotes!$B$2:$B$301,A11,Quotes!$G$2:$G$301,"Y"))) | O11: =IF(A11="","",AND(E11,G11="Y")) -> FALSE | P11: =IF(A11="","",IF(AND(O11,N11<>""),N11,"")) | Q11: =IF(A11="","",COUNTIF(Picks!$A$2:$A$301,A11)>0) -> FALSE | R11: 30 | T11: =IF(A11="","",COUNTIF(Nudges!$C$2:$C$301,A11)>0) -> TRUE
A12: R011 | B12: 46340.771 | C12: =IF(B12="","",INT((B12-Settings!$B$2)/7)+1) -> 2 | D12: pool_cleaning | E12: =IF(A12="","",OR(D12=Settings!$B$3,AND(Settings!$B$4<>"",D12=Settings!$B$4))) -> TRUE | F12: Organic | G12: Y | H12: Test Homeowner 11 | I12: 110 Test St, Lake Havasu City | J12: homeowner11@example.com | K12: 46340.854 | L12: Y | M12: =IF(A12="","",COUNTIFS(Quotes!$B$2:$B$301,A12,Quotes!$G$2:$G$301,"Y")) -> 0 | N12: =IF(A12="","",IF(M12=0,"",_xlfn.MINIFS(Quotes!$F$2:$F$301,Quotes!$B$2:$B$301,A12,Quotes!$G$2:$G$301,"Y"))) | O12: =IF(A12="","",AND(E12,G12="Y")) -> TRUE | P12: =IF(A12="","",IF(AND(O12,N12<>""),N12,"")) | Q12: =IF(A12="","",COUNTIF(Picks!$A$2:$A$301,A12)>0) -> FALSE | R12: 25 | T12: =IF(A12="","",COUNTIF(Nudges!$C$2:$C$301,A12)>0) -> FALSE
A13: R012 | B13: 46343.698 | C13: =IF(B13="","",INT((B13-Settings!$B$2)/7)+1) -> 3 | D13: pool_cleaning | E13: =IF(A13="","",OR(D13=Settings!$B$3,AND(Settings!$B$4<>"",D13=Settings!$B$4))) -> TRUE | F13: Organic | G13: Y | H13: Test Homeowner 12 | I13: 111 Test St, Lake Havasu City | J13: homeowner12@example.com | K13: 46343.823 | L13: N | M13: =IF(A13="","",COUNTIFS(Quotes!$B$2:$B$301,A13,Quotes!$G$2:$G$301,"Y")) -> 1 | N13: =IF(A13="","",IF(M13=0,"",_xlfn.MINIFS(Quotes!$F$2:$F$301,Quotes!$B$2:$B$301,A13,Quotes!$G$2:$G$301,"Y"))) -> 3.5548196 | O13: =IF(A13="","",AND(E13,G13="Y")) -> TRUE | P13: =IF(A13="","",IF(AND(O13,N13<>""),N13,"")) -> 3.5548196 | Q13: =IF(A13="","",COUNTIF(Picks!$A$2:$A$301,A13)>0) -> FALSE | R13: 40 | S13: No reply | T13: =IF(A13="","",COUNTIF(Nudges!$C$2:$C$301,A13)>0) -> FALSE
A14: R013 | B14: 46343.708 | C14: =IF(B14="","",INT((B14-Settings!$B$2)/7)+1) -> 3 | D14: house_cleaning | E14: =IF(A14="","",OR(D14=Settings!$B$3,AND(Settings!$B$4<>"",D14=Settings!$B$4))) -> FALSE | F14: Partner | G14: Y | H14: Test Homeowner 13 | I14: 112 Test St, Lake Havasu City | J14: homeowner13@example.com | K14: 46343.75 | L14: N | M14: =IF(A14="","",COUNTIFS(Quotes!$B$2:$B$301,A14,Quotes!$G$2:$G$301,"Y")) -> 0 | N14: =IF(A14="","",IF(M14=0,"",_xlfn.MINIFS(Quotes!$F$2:$F$301,Quotes!$B$2:$B$301,A14,Quotes!$G$2:$G$301,"Y"))) | O14: =IF(A14="","",AND(E14,G14="Y")) -> FALSE | P14: =IF(A14="","",IF(AND(O14,N14<>""),N14,"")) | Q14: =IF(A14="","",COUNTIF(Picks!$A$2:$A$301,A14)>0) -> FALSE | R14: 30 | T14: =IF(A14="","",COUNTIF(Nudges!$C$2:$C$301,A14)>0) -> FALSE
A15: R014 | B15: 46345.708 | C15: =IF(B15="","",INT((B15-Settings!$B$2)/7)+1) -> 3 | D15: pool_cleaning | E15: =IF(A15="","",OR(D15=Settings!$B$3,AND(Settings!$B$4<>"",D15=Settings!$B$4))) -> TRUE | F15: Organic | G15: Y | H15: Test Homeowner 14 | I15: 113 Test St, Lake Havasu City | J15: homeowner14@example.com | K15: 46345.75 | L15: Y | M15: =IF(A15="","",COUNTIFS(Quotes!$B$2:$B$301,A15,Quotes!$G$2:$G$301,"Y")) -> 3 | N15: =IF(A15="","",IF(M15=0,"",_xlfn.MINIFS(Quotes!$F$2:$F$301,Quotes!$B$2:$B$301,A15,Quotes!$G$2:$G$301,"Y"))) -> 0.92567684 | O15: =IF(A15="","",AND(E15,G15="Y")) -> TRUE | P15: =IF(A15="","",IF(AND(O15,N15<>""),N15,"")) -> 0.92567684 | Q15: =IF(A15="","",COUNTIF(Picks!$A$2:$A$301,A15)>0) -> TRUE | R15: 30 | T15: =IF(A15="","",COUNTIF(Nudges!$C$2:$C$301,A15)>0) -> FALSE
A16: R015 | B16: 46346.469 | C16: =IF(B16="","",INT((B16-Settings!$B$2)/7)+1) -> 3 | D16: pool_cleaning | E16: =IF(A16="","",OR(D16=Settings!$B$3,AND(Settings!$B$4<>"",D16=Settings!$B$4))) -> TRUE | F16: Seeded | G16: Y | H16: Test Homeowner 15 | I16: 114 Test St, Lake Havasu City | J16: homeowner15@example.com | K16: 46346.51 | L16: Y | M16: =IF(A16="","",COUNTIFS(Quotes!$B$2:$B$301,A16,Quotes!$G$2:$G$301,"Y")) -> 2 | N16: =IF(A16="","",IF(M16=0,"",_xlfn.MINIFS(Quotes!$F$2:$F$301,Quotes!$B$2:$B$301,A16,Quotes!$G$2:$G$301,"Y"))) -> 1.1363805 | O16: =IF(A16="","",AND(E16,G16="Y")) -> TRUE | P16: =IF(A16="","",IF(AND(O16,N16<>""),N16,"")) -> 1.1363805 | Q16: =IF(A16="","",COUNTIF(Picks!$A$2:$A$301,A16)>0) -> FALSE | R16: 40 | S16: Prices too high | T16: =IF(A16="","",COUNTIF(Nudges!$C$2:$C$301,A16)>0) -> TRUE
A17: R016 | B17: 46348.49 | C17: =IF(B17="","",INT((B17-Settings!$B$2)/7)+1) -> 3 | D17: handyman | E17: =IF(A17="","",OR(D17=Settings!$B$3,AND(Settings!$B$4<>"",D17=Settings!$B$4))) -> TRUE | F17: Partner | G17: Y | H17: Test Homeowner 16 | I17: 115 Test St, Lake Havasu City | J17: homeowner16@example.com | K17: 46348.615 | L17: N | M17: =IF(A17="","",COUNTIFS(Quotes!$B$2:$B$301,A17,Quotes!$G$2:$G$301,"Y")) -> 1 | N17: =IF(A17="","",IF(M17=0,"",_xlfn.MINIFS(Quotes!$F$2:$F$301,Quotes!$B$2:$B$301,A17,Quotes!$G$2:$G$301,"Y"))) -> 2.4970822 | O17: =IF(A17="","",AND(E17,G17="Y")) -> TRUE | P17: =IF(A17="","",IF(AND(O17,N17<>""),N17,"")) -> 2.4970822 | Q17: =IF(A17="","",COUNTIF(Picks!$A$2:$A$301,A17)>0) -> FALSE | R17: 35 | S17: Went with someone she already knew | T17: =IF(A17="","",COUNTIF(Nudges!$C$2:$C$301,A17)>0) -> FALSE
A18: R017 | B18: 46348.438 | C18: =IF(B18="","",INT((B18-Settings!$B$2)/7)+1) -> 3 | D18: handyman | E18: =IF(A18="","",OR(D18=Settings!$B$3,AND(Settings!$B$4<>"",D18=Settings!$B$4))) -> TRUE | F18: Organic | G18: Y | H18: Test Homeowner 17 | I18: 116 Test St, Lake Havasu City | J18: homeowner17@example.com | K18: 46348.479 | L18: Y | M18: =IF(A18="","",COUNTIFS(Quotes!$B$2:$B$301,A18,Quotes!$G$2:$G$301,"Y")) -> 2 | N18: =IF(A18="","",IF(M18=0,"",_xlfn.MINIFS(Quotes!$F$2:$F$301,Quotes!$B$2:$B$301,A18,Quotes!$G$2:$G$301,"Y"))) -> 1.4375091 | O18: =IF(A18="","",AND(E18,G18="Y")) -> TRUE | P18: =IF(A18="","",IF(AND(O18,N18<>""),N18,"")) -> 1.4375091 | Q18: =IF(A18="","",COUNTIF(Picks!$A$2:$A$301,A18)>0) -> TRUE | R18: 20 | T18: =IF(A18="","",COUNTIF(Nudges!$C$2:$C$301,A18)>0) -> TRUE
A19: R018 | B19: 46349.74 | C19: =IF(B19="","",INT((B19-Settings!$B$2)/7)+1) -> 4 | D19: handyman | E19: =IF(A19="","",OR(D19=Settings!$B$3,AND(Settings!$B$4<>"",D19=Settings!$B$4))) -> TRUE | F19: Partner | G19: Y | H19: Test Homeowner 18 | I19: 117 Test St, Lake Havasu City | J19: homeowner18@example.com | K19: 46349.781 | L19: Y | M19: =IF(A19="","",COUNTIFS(Quotes!$B$2:$B$301,A19,Quotes!$G$2:$G$301,"Y")) -> 3 | N19: =IF(A19="","",IF(M19=0,"",_xlfn.MINIFS(Quotes!$F$2:$F$301,Quotes!$B$2:$B$301,A19,Quotes!$G$2:$G$301,"Y"))) -> 1.0997859 | O19: =IF(A19="","",AND(E19,G19="Y")) -> TRUE | P19: =IF(A19="","",IF(AND(O19,N19<>""),N19,"")) -> 1.0997859 | Q19: =IF(A19="","",COUNTIF(Picks!$A$2:$A$301,A19)>0) -> TRUE | R19: 15 | T19: =IF(A19="","",COUNTIF(Nudges!$C$2:$C$301,A19)>0) -> FALSE
A20: R019 | B20: 46352.729 | C20: =IF(B20="","",INT((B20-Settings!$B$2)/7)+1) -> 4 | D20: hvac_repair | E20: =IF(A20="","",OR(D20=Settings!$B$3,AND(Settings!$B$4<>"",D20=Settings!$B$4))) -> FALSE | F20: Partner | G20: Y | H20: Test Homeowner 19 | I20: 118 Test St, Lake Havasu City | J20: homeowner19@example.com | K20: 46352.771 | L20: N | M20: =IF(A20="","",COUNTIFS(Quotes!$B$2:$B$301,A20,Quotes!$G$2:$G$301,"Y")) -> 0 | N20: =IF(A20="","",IF(M20=0,"",_xlfn.MINIFS(Quotes!$F$2:$F$301,Quotes!$B$2:$B$301,A20,Quotes!$G$2:$G$301,"Y"))) | O20: =IF(A20="","",AND(E20,G20="Y")) -> FALSE | P20: =IF(A20="","",IF(AND(O20,N20<>""),N20,"")) | Q20: =IF(A20="","",COUNTIF(Picks!$A$2:$A$301,A20)>0) -> FALSE | R20: 25 | T20: =IF(A20="","",COUNTIF(Nudges!$C$2:$C$301,A20)>0) -> FALSE
A21: R020 | B21: 46353.458 | C21: =IF(B21="","",INT((B21-Settings!$B$2)/7)+1) -> 4 | D21: hvac_repair | E21: =IF(A21="","",OR(D21=Settings!$B$3,AND(Settings!$B$4<>"",D21=Settings!$B$4))) -> FALSE | F21: Partner | G21: Y | H21: Test Homeowner 20 | I21: 119 Test St, Lake Havasu City | J21: homeowner20@example.com | K21: 46353.542 | L21: Y | M21: =IF(A21="","",COUNTIFS(Quotes!$B$2:$B$301,A21,Quotes!$G$2:$G$301,"Y")) -> 1 | N21: =IF(A21="","",IF(M21=0,"",_xlfn.MINIFS(Quotes!$F$2:$F$301,Quotes!$B$2:$B$301,A21,Quotes!$G$2:$G$301,"Y"))) -> 8.0378851 | O21: =IF(A21="","",AND(E21,G21="Y")) -> FALSE | P21: =IF(A21="","",IF(AND(O21,N21<>""),N21,"")) | Q21: =IF(A21="","",COUNTIF(Picks!$A$2:$A$301,A21)>0) -> TRUE | R21: 15 | T21: =IF(A21="","",COUNTIF(Nudges!$C$2:$C$301,A21)>0) -> FALSE
A22: R021 | B22: 46353.427 | C22: =IF(B22="","",INT((B22-Settings!$B$2)/7)+1) -> 4 | D22: handyman | E22: =IF(A22="","",OR(D22=Settings!$B$3,AND(Settings!$B$4<>"",D22=Settings!$B$4))) -> TRUE | F22: Organic | G22: Y | H22: Test Homeowner 21 | I22: 120 Test St, Lake Havasu City | J22: homeowner21@example.com | K22: 46353.552 | L22: Y | M22: =IF(A22="","",COUNTIFS(Quotes!$B$2:$B$301,A22,Quotes!$G$2:$G$301,"Y")) -> 3 | N22: =IF(A22="","",IF(M22=0,"",_xlfn.MINIFS(Quotes!$F$2:$F$301,Quotes!$B$2:$B$301,A22,Quotes!$G$2:$G$301,"Y"))) -> 3.6249041 | O22: =IF(A22="","",AND(E22,G22="Y")) -> TRUE | P22: =IF(A22="","",IF(AND(O22,N22<>""),N22,"")) -> 3.6249041 | Q22: =IF(A22="","",COUNTIF(Picks!$A$2:$A$301,A22)>0) -> TRUE | R22: 25 | T22: =IF(A22="","",COUNTIF(Nudges!$C$2:$C$301,A22)>0) -> FALSE
A23: R022 | B23: 46354.792 | C23: =IF(B23="","",INT((B23-Settings!$B$2)/7)+1) -> 4 | D23: handyman | E23: =IF(A23="","",OR(D23=Settings!$B$3,AND(Settings!$B$4<>"",D23=Settings!$B$4))) -> TRUE | F23: Organic | G23: Y | H23: Test Homeowner 22 | I23: 121 Test St, Lake Havasu City | J23: homeowner22@example.com | K23: 46354.917 | L23: Y | M23: =IF(A23="","",COUNTIFS(Quotes!$B$2:$B$301,A23,Quotes!$G$2:$G$301,"Y")) -> 4 | N23: =IF(A23="","",IF(M23=0,"",_xlfn.MINIFS(Quotes!$F$2:$F$301,Quotes!$B$2:$B$301,A23,Quotes!$G$2:$G$301,"Y"))) -> 2.774763 | O23: =IF(A23="","",AND(E23,G23="Y")) -> TRUE | P23: =IF(A23="","",IF(AND(O23,N23<>""),N23,"")) -> 2.774763 | Q23: =IF(A23="","",COUNTIF(Picks!$A$2:$A$301,A23)>0) -> FALSE | R23: 25 | S23: No reply | T23: =IF(A23="","",COUNTIF(Nudges!$C$2:$C$301,A23)>0) -> FALSE
A24: R023 | B24: 46357.635 | C24: =IF(B24="","",INT((B24-Settings!$B$2)/7)+1) -> 5 | D24: plumbing_repair | E24: =IF(A24="","",OR(D24=Settings!$B$3,AND(Settings!$B$4<>"",D24=Settings!$B$4))) -> FALSE | F24: Organic | G24: N | H24: Test Homeowner 23 | I24: 122 Test St, Lake Havasu City | J24: homeowner23@example.com | M24: =IF(A24="","",COUNTIFS(Quotes!$B$2:$B$301,A24,Quotes!$G$2:$G$301,"Y")) -> 0 | N24: =IF(A24="","",IF(M24=0,"",_xlfn.MINIFS(Quotes!$F$2:$F$301,Quotes!$B$2:$B$301,A24,Quotes!$G$2:$G$301,"Y"))) | O24: =IF(A24="","",AND(E24,G24="Y")) -> FALSE | P24: =IF(A24="","",IF(AND(O24,N24<>""),N24,"")) | Q24: =IF(A24="","",COUNTIF(Picks!$A$2:$A$301,A24)>0) -> FALSE | R24: 20 | S24: Not covered (template A) | T24: =IF(A24="","",COUNTIF(Nudges!$C$2:$C$301,A24)>0) -> FALSE
A25: R024 | B25: 46357.75 | C25: =IF(B25="","",INT((B25-Settings!$B$2)/7)+1) -> 5 | D25: pool_cleaning | E25: =IF(A25="","",OR(D25=Settings!$B$3,AND(Settings!$B$4<>"",D25=Settings!$B$4))) -> TRUE | F25: Seeded | G25: Y | H25: Test Homeowner 24 | I25: 123 Test St, Lake Havasu City | J25: homeowner24@example.com | K25: 46357.792 | L25: N | M25: =IF(A25="","",COUNTIFS(Quotes!$B$2:$B$301,A25,Quotes!$G$2:$G$301,"Y")) -> 1 | N25: =IF(A25="","",IF(M25=0,"",_xlfn.MINIFS(Quotes!$F$2:$F$301,Quotes!$B$2:$B$301,A25,Quotes!$G$2:$G$301,"Y"))) -> 2.2806052 | O25: =IF(A25="","",AND(E25,G25="Y")) -> TRUE | P25: =IF(A25="","",IF(AND(O25,N25<>""),N25,"")) -> 2.2806052 | Q25: =IF(A25="","",COUNTIF(Picks!$A$2:$A$301,A25)>0) -> TRUE | R25: 25 | T25: =IF(A25="","",COUNTIF(Nudges!$C$2:$C$301,A25)>0) -> FALSE
A26: R025 | B26: 46358.646 | C26: =IF(B26="","",INT((B26-Settings!$B$2)/7)+1) -> 5 | D26: handyman | E26: =IF(A26="","",OR(D26=Settings!$B$3,AND(Settings!$B$4<>"",D26=Settings!$B$4))) -> TRUE | F26: Organic | G26: Y | H26: Test Homeowner 25 | I26: 124 Test St, Lake Havasu City | J26: homeowner25@example.com | K26: 46358.729 | L26: N | M26: =IF(A26="","",COUNTIFS(Quotes!$B$2:$B$301,A26,Quotes!$G$2:$G$301,"Y")) -> 4 | N26: =IF(A26="","",IF(M26=0,"",_xlfn.MINIFS(Quotes!$F$2:$F$301,Quotes!$B$2:$B$301,A26,Quotes!$G$2:$G$301,"Y"))) -> 2.8600961 | O26: =IF(A26="","",AND(E26,G26="Y")) -> TRUE | P26: =IF(A26="","",IF(AND(O26,N26<>""),N26,"")) -> 2.8600961 | Q26: =IF(A26="","",COUNTIF(Picks!$A$2:$A$301,A26)>0) -> FALSE | R26: 15 | S26: Prices too high | T26: =IF(A26="","",COUNTIF(Nudges!$C$2:$C$301,A26)>0) -> FALSE
A27: R026 | B27: 46361.667 | C27: =IF(B27="","",INT((B27-Settings!$B$2)/7)+1) -> 5 | D27: pool_cleaning | E27: =IF(A27="","",OR(D27=Settings!$B$3,AND(Settings!$B$4<>"",D27=Settings!$B$4))) -> TRUE | F27: Seeded | G27: Y | H27: Test Homeowner 26 | I27: 125 Test St, Lake Havasu City | J27: homeowner26@example.com | K27: 46361.792 | L27: N | M27: =IF(A27="","",COUNTIFS(Quotes!$B$2:$B$301,A27,Quotes!$G$2:$G$301,"Y")) -> 1 | N27: =IF(A27="","",IF(M27=0,"",_xlfn.MINIFS(Quotes!$F$2:$F$301,Quotes!$B$2:$B$301,A27,Quotes!$G$2:$G$301,"Y"))) -> 9.9099622 | O27: =IF(A27="","",AND(E27,G27="Y")) -> TRUE | P27: =IF(A27="","",IF(AND(O27,N27<>""),N27,"")) -> 9.9099622 | Q27: =IF(A27="","",COUNTIF(Picks!$A$2:$A$301,A27)>0) -> FALSE | R27: 20 | S27: No reply | T27: =IF(A27="","",COUNTIF(Nudges!$C$2:$C$301,A27)>0) -> FALSE
A28: R027 | B28: 46362.698 | C28: =IF(B28="","",INT((B28-Settings!$B$2)/7)+1) -> 5 | D28: handyman | E28: =IF(A28="","",OR(D28=Settings!$B$3,AND(Settings!$B$4<>"",D28=Settings!$B$4))) -> TRUE | F28: Organic | G28: Y | H28: Test Homeowner 27 | I28: 126 Test St, Lake Havasu City | J28: homeowner27@example.com | K28: 46362.74 | L28: N | M28: =IF(A28="","",COUNTIFS(Quotes!$B$2:$B$301,A28,Quotes!$G$2:$G$301,"Y")) -> 0 | N28: =IF(A28="","",IF(M28=0,"",_xlfn.MINIFS(Quotes!$F$2:$F$301,Quotes!$B$2:$B$301,A28,Quotes!$G$2:$G$301,"Y"))) | O28: =IF(A28="","",AND(E28,G28="Y")) -> TRUE | P28: =IF(A28="","",IF(AND(O28,N28<>""),N28,"")) | Q28: =IF(A28="","",COUNTIF(Picks!$A$2:$A$301,A28)>0) -> FALSE | R28: 20 | T28: =IF(A28="","",COUNTIF(Nudges!$C$2:$C$301,A28)>0) -> FALSE
A29: R028 | B29: 46362.583 | C29: =IF(B29="","",INT((B29-Settings!$B$2)/7)+1) -> 5 | D29: handyman | E29: =IF(A29="","",OR(D29=Settings!$B$3,AND(Settings!$B$4<>"",D29=Settings!$B$4))) -> TRUE | F29: Seeded | G29: Y | H29: Test Homeowner 28 | I29: 127 Test St, Lake Havasu City | J29: homeowner28@example.com | K29: 46362.667 | L29: N | M29: =IF(A29="","",COUNTIFS(Quotes!$B$2:$B$301,A29,Quotes!$G$2:$G$301,"Y")) -> 2 | N29: =IF(A29="","",IF(M29=0,"",_xlfn.MINIFS(Quotes!$F$2:$F$301,Quotes!$B$2:$B$301,A29,Quotes!$G$2:$G$301,"Y"))) -> 3.897185 | O29: =IF(A29="","",AND(E29,G29="Y")) -> TRUE | P29: =IF(A29="","",IF(AND(O29,N29<>""),N29,"")) -> 3.897185 | Q29: =IF(A29="","",COUNTIF(Picks!$A$2:$A$301,A29)>0) -> TRUE | R29: 25 | T29: =IF(A29="","",COUNTIF(Nudges!$C$2:$C$301,A29)>0) -> FALSE
A30: R029 | B30: 46363.458 | C30: =IF(B30="","",INT((B30-Settings!$B$2)/7)+1) -> 6 | D30: plumbing_repair | E30: =IF(A30="","",OR(D30=Settings!$B$3,AND(Settings!$B$4<>"",D30=Settings!$B$4))) -> FALSE | F30: Organic | G30: N | H30: Test Homeowner 29 | I30: 128 Test St, Lake Havasu City | J30: homeowner29@example.com | M30: =IF(A30="","",COUNTIFS(Quotes!$B$2:$B$301,A30,Quotes!$G$2:$G$301,"Y")) -> 0 | N30: =IF(A30="","",IF(M30=0,"",_xlfn.MINIFS(Quotes!$F$2:$F$301,Quotes!$B$2:$B$301,A30,Quotes!$G$2:$G$301,"Y"))) | O30: =IF(A30="","",AND(E30,G30="Y")) -> FALSE | P30: =IF(A30="","",IF(AND(O30,N30<>""),N30,"")) | Q30: =IF(A30="","",COUNTIF(Picks!$A$2:$A$301,A30)>0) -> FALSE | R30: 30 | S30: Not covered (template A) | T30: =IF(A30="","",COUNTIF(Nudges!$C$2:$C$301,A30)>0) -> FALSE
A31: R030 | B31: 46366.781 | C31: =IF(B31="","",INT((B31-Settings!$B$2)/7)+1) -> 6 | D31: pool_cleaning | E31: =IF(A31="","",OR(D31=Settings!$B$3,AND(Settings!$B$4<>"",D31=Settings!$B$4))) -> TRUE | F31: Organic | G31: Y | H31: Test Homeowner 30 | I31: 129 Test St, Lake Havasu City | J31: homeowner30@example.com | K31: 46366.823 | L31: N | M31: =IF(A31="","",COUNTIFS(Quotes!$B$2:$B$301,A31,Quotes!$G$2:$G$301,"Y")) -> 3 | N31: =IF(A31="","",IF(M31=0,"",_xlfn.MINIFS(Quotes!$F$2:$F$301,Quotes!$B$2:$B$301,A31,Quotes!$G$2:$G$301,"Y"))) -> 1.2833015 | O31: =IF(A31="","",AND(E31,G31="Y")) -> TRUE | P31: =IF(A31="","",IF(AND(O31,N31<>""),N31,"")) -> 1.2833015 | Q31: =IF(A31="","",COUNTIF(Picks!$A$2:$A$301,A31)>0) -> TRUE | R31: 30 | T31: =IF(A31="","",COUNTIF(Nudges!$C$2:$C$301,A31)>0) -> FALSE
A32: R031 | B32: 46367.375 | C32: =IF(B32="","",INT((B32-Settings!$B$2)/7)+1) -> 6 | D32: pool_cleaning | E32: =IF(A32="","",OR(D32=Settings!$B$3,AND(Settings!$B$4<>"",D32=Settings!$B$4))) -> TRUE | F32: Seeded | G32: Y | H32: Test Homeowner 31 | I32: 130 Test St, Lake Havasu City | J32: homeowner31@example.com | K32: 46367.417 | L32: Y | M32: =IF(A32="","",COUNTIFS(Quotes!$B$2:$B$301,A32,Quotes!$G$2:$G$301,"Y")) -> 0 | N32: =IF(A32="","",IF(M32=0,"",_xlfn.MINIFS(Quotes!$F$2:$F$301,Quotes!$B$2:$B$301,A32,Quotes!$G$2:$G$301,"Y"))) | O32: =IF(A32="","",AND(E32,G32="Y")) -> TRUE | P32: =IF(A32="","",IF(AND(O32,N32<>""),N32,"")) | Q32: =IF(A32="","",COUNTIF(Picks!$A$2:$A$301,A32)>0) -> FALSE | R32: 30 | T32: =IF(A32="","",COUNTIF(Nudges!$C$2:$C$301,A32)>0) -> FALSE
A33: R032 | B33: 46368.531 | C33: =IF(B33="","",INT((B33-Settings!$B$2)/7)+1) -> 6 | D33: hvac_repair | E33: =IF(A33="","",OR(D33=Settings!$B$3,AND(Settings!$B$4<>"",D33=Settings!$B$4))) -> FALSE | F33: Organic | G33: Y | H33: Test Homeowner 32 | I33: 131 Test St, Lake Havasu City | J33: homeowner32@example.com | K33: 46368.615 | L33: N | M33: =IF(A33="","",COUNTIFS(Quotes!$B$2:$B$301,A33,Quotes!$G$2:$G$301,"Y")) -> 0 | N33: =IF(A33="","",IF(M33=0,"",_xlfn.MINIFS(Quotes!$F$2:$F$301,Quotes!$B$2:$B$301,A33,Quotes!$G$2:$G$301,"Y"))) | O33: =IF(A33="","",AND(E33,G33="Y")) -> FALSE | P33: =IF(A33="","",IF(AND(O33,N33<>""),N33,"")) | Q33: =IF(A33="","",COUNTIF(Picks!$A$2:$A$301,A33)>0) -> FALSE | R33: 30 | T33: =IF(A33="","",COUNTIF(Nudges!$C$2:$C$301,A33)>0) -> FALSE
C34: =IF(B34="","",INT((B34-Settings!$B$2)/7)+1) | E34: =IF(A34="","",OR(D34=Settings!$B$3,AND(Settings!$B$4<>"",D34=Settings!$B$4))) | M34: =IF(A34="","",COUNTIFS(Quotes!$B$2:$B$301,A34,Quotes!$G$2:$G$301,"Y")) | N34: =IF(A34="","",IF(M34=0,"",_xlfn.MINIFS(Quotes!$F$2:$F$301,Quotes!$B$2:$B$301,A34,Quotes!$G$2:$G$301,"Y"))) | O34: =IF(A34="","",AND(E34,G34="Y")) | P34: =IF(A34="","",IF(AND(O34,N34<>""),N34,"")) | Q34: =IF(A34="","",COUNTIF(Picks!$A$2:$A$301,A34)>0) | T34: =IF(A34="","",COUNTIF(Nudges!$C$2:$C$301,A34)>0)
C35: =IF(B35="","",INT((B35-Settings!$B$2)/7)+1) | E35: =IF(A35="","",OR(D35=Settings!$B$3,AND(Settings!$B$4<>"",D35=Settings!$B$4))) | M35: =IF(A35="","",COUNTIFS(Quotes!$B$2:$B$301,A35,Quotes!$G$2:$G$301,"Y")) | N35: =IF(A35="","",IF(M35=0,"",_xlfn.MINIFS(Quotes!$F$2:$F$301,Quotes!$B$2:$B$301,A35,Quotes!$G$2:$G$301,"Y"))) | O35: =IF(A35="","",AND(E35,G35="Y")) | P35: =IF(A35="","",IF(AND(O35,N35<>""),N35,"")) | Q35: =IF(A35="","",COUNTIF(Picks!$A$2:$A$301,A35)>0) | T35: =IF(A35="","",COUNTIF(Nudges!$C$2:$C$301,A35)>0)
C36: =IF(B36="","",INT((B36-Settings!$B$2)/7)+1) | E36: =IF(A36="","",OR(D36=Settings!$B$3,AND(Settings!$B$4<>"",D36=Settings!$B$4))) | M36: =IF(A36="","",COUNTIFS(Quotes!$B$2:$B$301,A36,Quotes!$G$2:$G$301,"Y")) | N36: =IF(A36="","",IF(M36=0,"",_xlfn.MINIFS(Quotes!$F$2:$F$301,Quotes!$B$2:$B$301,A36,Quotes!$G$2:$G$301,"Y"))) | O36: =IF(A36="","",AND(E36,G36="Y")) | P36: =IF(A36="","",IF(AND(O36,N36<>""),N36,"")) | Q36: =IF(A36="","",COUNTIF(Picks!$A$2:$A$301,A36)>0) | T36: =IF(A36="","",COUNTIF(Nudges!$C$2:$C$301,A36)>0)
C37: =IF(B37="","",INT((B37-Settings!$B$2)/7)+1) | E37: =IF(A37="","",OR(D37=Settings!$B$3,AND(Settings!$B$4<>"",D37=Settings!$B$4))) | M37: =IF(A37="","",COUNTIFS(Quotes!$B$2:$B$301,A37,Quotes!$G$2:$G$301,"Y")) | N37: =IF(A37="","",IF(M37=0,"",_xlfn.MINIFS(Quotes!$F$2:$F$301,Quotes!$B$2:$B$301,A37,Quotes!$G$2:$G$301,"Y"))) | O37: =IF(A37="","",AND(E37,G37="Y")) | P37: =IF(A37="","",IF(AND(O37,N37<>""),N37,"")) | Q37: =IF(A37="","",COUNTIF(Picks!$A$2:$A$301,A37)>0) | T37: =IF(A37="","",COUNTIF(Nudges!$C$2:$C$301,A37)>0)
C38: =IF(B38="","",INT((B38-Settings!$B$2)/7)+1) | E38: =IF(A38="","",OR(D38=Settings!$B$3,AND(Settings!$B$4<>"",D38=Settings!$B$4))) | M38: =IF(A38="","",COUNTIFS(Quotes!$B$2:$B$301,A38,Quotes!$G$2:$G$301,"Y")) | N38: =IF(A38="","",IF(M38=0,"",_xlfn.MINIFS(Quotes!$F$2:$F$301,Quotes!$B$2:$B$301,A38,Quotes!$G$2:$G$301,"Y"))) | O38: =IF(A38="","",AND(E38,G38="Y")) | P38: =IF(A38="","",IF(AND(O38,N38<>""),N38,"")) | Q38: =IF(A38="","",COUNTIF(Picks!$A$2:$A$301,A38)>0) | T38: =IF(A38="","",COUNTIF(Nudges!$C$2:$C$301,A38)>0)
C39: =IF(B39="","",INT((B39-Settings!$B$2)/7)+1) | E39: =IF(A39="","",OR(D39=Settings!$B$3,AND(Settings!$B$4<>"",D39=Settings!$B$4))) | M39: =IF(A39="","",COUNTIFS(Quotes!$B$2:$B$301,A39,Quotes!$G$2:$G$301,"Y")) | N39: =IF(A39="","",IF(M39=0,"",_xlfn.MINIFS(Quotes!$F$2:$F$301,Quotes!$B$2:$B$301,A39,Quotes!$G$2:$G$301,"Y"))) | O39: =IF(A39="","",AND(E39,G39="Y")) | P39: =IF(A39="","",IF(AND(O39,N39<>""),N39,"")) | Q39: =IF(A39="","",COUNTIF(Picks!$A$2:$A$301,A39)>0) | T39: =IF(A39="","",COUNTIF(Nudges!$C$2:$C$301,A39)>0)
C40: =IF(B40="","",INT((B40-Settings!$B$2)/7)+1) | E40: =IF(A40="","",OR(D40=Settings!$B$3,AND(Settings!$B$4<>"",D40=Settings!$B$4))) | M40: =IF(A40="","",COUNTIFS(Quotes!$B$2:$B$301,A40,Quotes!$G$2:$G$301,"Y")) | N40: =IF(A40="","",IF(M40=0,"",_xlfn.MINIFS(Quotes!$F$2:$F$301,Quotes!$B$2:$B$301,A40,Quotes!$G$2:$G$301,"Y"))) | O40: =IF(A40="","",AND(E40,G40="Y")) | P40: =IF(A40="","",IF(AND(O40,N40<>""),N40,"")) | Q40: =IF(A40="","",COUNTIF(Picks!$A$2:$A$301,A40)>0) | T40: =IF(A40="","",COUNTIF(Nudges!$C$2:$C$301,A40)>0)
...

Sheet Quotes
A1: Quote ID | B1: Request ID | C1: Business ID | D1: Received | E1: Price ($; range midpoint; ongoing = 4 months) | F1: Hours after card | G1: Valid in 24h (Y/N) | H1: Quote type | I1: Week | K1: FAKE TEST DATA in every row. Clear before the real test (Read me).
A2: Q001 | B2: R001 | C2: B09 | D2: 46329.134 | E2: 380 | F2: =IF(OR(B2="",D2=""),"",IFERROR((D2-INDEX(Requests!$K$2:$K$301,MATCH(B2,Requests!$A$2:$A$301,0)))*24,"")) -> 8.464606 | G2: =IF(F2="","",IF(F2<=24,"Y","N")) -> Y | H2: visit fee | I2: =IF(D2="","",INT((D2-Settings!$B$2)/7)+1) -> 1
A3: Q002 | B3: R001 | C3: B06 | D3: 46328.902 | E3: 150 | F3: =IF(OR(B3="",D3=""),"",IFERROR((D3-INDEX(Requests!$K$2:$K$301,MATCH(B3,Requests!$A$2:$A$301,0)))*24,"")) -> 2.8895749 | G3: =IF(F3="","",IF(F3<=24,"Y","N")) -> Y | H3: visit fee | I3: =IF(D3="","",INT((D3-Settings!$B$2)/7)+1) -> 1
A4: Q003 | B4: R002 | C4: B05 | D4: 46331.766 | E4: 520 | F4: =IF(OR(B4="",D4=""),"",IFERROR((D4-INDEX(Requests!$K$2:$K$301,MATCH(B4,Requests!$A$2:$A$301,0)))*24,"")) -> 25.884316 | G4: =IF(F4="","",IF(F4<=24,"Y","N")) -> N | H4: monthly x4 | I4: =IF(D4="","",INT((D4-Settings!$B$2)/7)+1) -> 1
A5: Q004 | B5: R003 | C5: B07 | D5: 46331.816 | E5: 220 | F5: =IF(OR(B5="",D5=""),"",IFERROR((D5-INDEX(Requests!$K$2:$K$301,MATCH(B5,Requests!$A$2:$A$301,0)))*24,"")) -> 7.3223721 | G5: =IF(F5="","",IF(F5<=24,"Y","N")) -> Y | H5: fixed | I5: =IF(D5="","",INT((D5-Settings!$B$2)/7)+1) -> 1
A6: Q005 | B6: R003 | C6: B09 | D6: 46331.839 | E6: 150 | F6: =IF(OR(B6="",D6=""),"",IFERROR((D6-INDEX(Requests!$K$2:$K$301,MATCH(B6,Requests!$A$2:$A$301,0)))*24,"")) -> 7.8797018 | G6: =IF(F6="","",IF(F6<=24,"Y","N")) -> Y | H6: visit fee | I6: =IF(D6="","",INT((D6-Settings!$B$2)/7)+1) -> 1
A7: Q006 | B7: R005 | C7: B01 | D7: 46334.456 | E7: 520 | F7: =IF(OR(B7="",D7=""),"",IFERROR((D7-INDEX(Requests!$K$2:$K$301,MATCH(B7,Requests!$A$2:$A$301,0)))*24,"")) -> 0.68401461 | G7: =IF(F7="","",IF(F7<=24,"Y","N")) -> Y | H7: monthly x4 | I7: =IF(D7="","",INT((D7-Settings!$B$2)/7)+1) -> 1
A8: Q007 | B8: R006 | C8: B04 | D8: 46336.104 | E8: 480 | F8: =IF(OR(B8="",D8=""),"",IFERROR((D8-INDEX(Requests!$K$2:$K$301,MATCH(B8,Requests!$A$2:$A$301,0)))*24,"")) -> 9.9973914 | G8: =IF(F8="","",IF(F8<=24,"Y","N")) -> Y | H8: monthly x4 | I8: =IF(D8="","",INT((D8-Settings!$B$2)/7)+1) -> 2
A9: Q008 | B9: R006 | C9: B05 | D9: 46335.785 | E9: 520 | F9: =IF(OR(B9="",D9=""),"",IFERROR((D9-INDEX(Requests!$K$2:$K$301,MATCH(B9,Requests!$A$2:$A$301,0)))*24,"")) -> 2.3489009 | G9: =IF(F9="","",IF(F9<=24,"Y","N")) -> Y | H9: monthly x4 | I9: =IF(D9="","",INT((D9-Settings!$B$2)/7)+1) -> 2
A10: Q009 | B10: R006 | C10: B02 | D10: 46335.794 | E10: 520 | F10: =IF(OR(B10="",D10=""),"",IFERROR((D10-INDEX(Requests!$K$2:$K$301,MATCH(B10,Requests!$A$2:$A$301,0)))*24,"")) -> 2.5595493 | G10: =IF(F10="","",IF(F10<=24,"Y","N")) -> Y | H10: monthly x4 | I10: =IF(D10="","",INT((D10-Settings!$B$2)/7)+1) -> 2
A11: Q010 | B11: R006 | C11: B03 | D11: 46335.795 | E11: 560 | F11: =IF(OR(B11="",D11=""),"",IFERROR((D11-INDEX(Requests!$K$2:$K$301,MATCH(B11,Requests!$A$2:$A$301,0)))*24,"")) -> 2.5871764 | G11: =IF(F11="","",IF(F11<=24,"Y","N")) -> Y | H11: monthly x4 | I11: =IF(D11="","",INT((D11-Settings!$B$2)/7)+1) -> 2
A12: Q011 | B12: R008 | C12: B10 | D12: 46336.831 | E12: 220 | F12: =IF(OR(B12="",D12=""),"",IFERROR((D12-INDEX(Requests!$K$2:$K$301,MATCH(B12,Requests!$A$2:$A$301,0)))*24,"")) -> 1.7040242 | G12: =IF(F12="","",IF(F12<=24,"Y","N")) -> Y | H12: range | I12: =IF(D12="","",INT((D12-Settings!$B$2)/7)+1) -> 2
A13: Q012 | B13: R008 | C13: B06 | D13: 46337.194 | E13: 650 | F13: =IF(OR(B13="",D13=""),"",IFERROR((D13-INDEX(Requests!$K$2:$K$301,MATCH(B13,Requests!$A$2:$A$301,0)))*24,"")) -> 10.406589 | G13: =IF(F13="","",IF(F13<=24,"Y","N")) -> Y | H13: visit fee | I13: =IF(D13="","",INT((D13-Settings!$B$2)/7)+1) -> 2
... A47: Q046 | B47: R030 | C47: B01 | D47: 46367.169 | E47: 520 | F47: =IF(OR(B47="",D47=""),"",IFERROR((D47-INDEX(Requests!$K$2:$K$301,MATCH(B47,Requests!$A$2:$A$301,0)))*24,"")) -> 8.2998105 | G47: =IF(F47="","",IF(F47<=24,"Y","N")) -> Y | H47: monthly x4 | I47: =IF(D47="","",INT((D47-Settings!$B$2)/7)+1) -> 6
F48: =IF(OR(B48="",D48=""),"",IFERROR((D48-INDEX(Requests!$K$2:$K$301,MATCH(B48,Requests!$A$2:$A$301,0)))*24,"")) | G48: =IF(F48="","",IF(F48<=24,"Y","N")) | I48: =IF(D48="","",INT((D48-Settings!$B$2)/7)+1)
F49: =IF(OR(B49="",D49=""),"",IFERROR((D49-INDEX(Requests!$K$2:$K$301,MATCH(B49,Requests!$A$2:$A$301,0)))*24,"")) | G49: =IF(F49="","",IF(F49<=24,"Y","N")) | I49: =IF(D49="","",INT((D49-Settings!$B$2)/7)+1)
F50: =IF(OR(B50="",D50=""),"",IFERROR((D50-INDEX(Requests!$K$2:$K$301,MATCH(B50,Requests!$A$2:$A$301,0)))*24,"")) | G50: =IF(F50="","",IF(F50<=24,"Y","N")) | I50: =IF(D50="","",INT((D50-Settings!$B$2)/7)+1)
F51: =IF(OR(B51="",D51=""),"",IFERROR((D51-INDEX(Requests!$K$2:$K$301,MATCH(B51,Requests!$A$2:$A$301,0)))*24,"")) | G51: =IF(F51="","",IF(F51<=24,"Y","N")) | I51: =IF(D51="","",INT((D51-Settings!$B$2)/7)+1)
F52: =IF(OR(B52="",D52=""),"",IFERROR((D52-INDEX(Requests!$K$2:$K$301,MATCH(B52,Requests!$A$2:$A$301,0)))*24,"")) | G52: =IF(F52="","",IF(F52<=24,"Y","N")) | I52: =IF(D52="","",INT((D52-Settings!$B$2)/7)+1)
F53: =IF(OR(B53="",D53=""),"",IFERROR((D53-INDEX(Requests!$K$2:$K$301,MATCH(B53,Requests!$A$2:$A$301,0)))*24,"")) | G53: =IF(F53="","",IF(F53<=24,"Y","N")) | I53: =IF(D53="","",INT((D53-Settings!$B$2)/7)+1)
F54: =IF(OR(B54="",D54=""),"",IFERROR((D54-INDEX(Requests!$K$2:$K$301,MATCH(B54,Requests!$A$2:$A$301,0)))*24,"")) | G54: =IF(F54="","",IF(F54<=24,"Y","N")) | I54: =IF(D54="","",INT((D54-Settings!$B$2)/7)+1)
F55: =IF(OR(B55="",D55=""),"",IFERROR((D55-INDEX(Requests!$K$2:$K$301,MATCH(B55,Requests!$A$2:$A$301,0)))*24,"")) | G55: =IF(F55="","",IF(F55<=24,"Y","N")) | I55: =IF(D55="","",INT((D55-Settings!$B$2)/7)+1)
F56: =IF(OR(B56="",D56=""),"",IFERROR((D56-INDEX(Requests!$K$2:$K$301,MATCH(B56,Requests!$A$2:$A$301,0)))*24,"")) | G56: =IF(F56="","",IF(F56<=24,"Y","N")) | I56: =IF(D56="","",INT((D56-Settings!$B$2)/7)+1)
F57: =IF(OR(B57="",D57=""),"",IFERROR((D57-INDEX(Requests!$K$2:$K$301,MATCH(B57,Requests!$A$2:$A$301,0)))*24,"")) | G57: =IF(F57="","",IF(F57<=24,"Y","N")) | I57: =IF(D57="","",INT((D57-Settings!$B$2)/7)+1)
F58: =IF(OR(B58="",D58=""),"",IFERROR((D58-INDEX(Requests!$K$2:$K$301,MATCH(B58,Requests!$A$2:$A$301,0)))*24,"")) | G58: =IF(F58="","",IF(F58<=24,"Y","N")) | I58: =IF(D58="","",INT((D58-Settings!$B$2)/7)+1)
F59: =IF(OR(B59="",D59=""),"",IFERROR((D59-INDEX(Requests!$K$2:$K$301,MATCH(B59,Requests!$A$2:$A$301,0)))*24,"")) | G59: =IF(F59="","",IF(F59<=24,"Y","N")) | I59: =IF(D59="","",INT((D59-Settings!$B$2)/7)+1)
... F301: =IF(OR(B301="",D301=""),"",IFERROR((D301-INDEX(Requests!$K$2:$K$301,MATCH(B301,Requests!$A$2:$A$301,0)))*24,"")) | G301: =IF(F301="","",IF(F301<=24,"Y","N")) | I301: =IF(D301="","",INT((D301-Settings!$B$2)/7)+1)

Sheet Picks
A1: Request ID | B1: Picked on | C1: Business ID | D1: Quote price ($) | E1: Introduction fee ($) | F1: Week | G1: Paid week | H1: Paid? (Y / Refused / blank) | I1: Refunded (Y/N) | J1: Pushed trade | K1: First payment from this business | M1: FAKE TEST DATA in every row. Clear before the real test (Read me).
A2: R008 | B2: 46337.76 | C2: B07 | D2: =IF(A2="","",SUMIFS(Quotes!$E$2:$E$301,Quotes!$B$2:$B$301,A2,Quotes!$C$2:$C$301,C2)) -> 900 | E2: =IF(A2="","",IF(D2<500,25,IF(D2<=1500,75,199))) -> 75 | F2: =IF(B2="","",INT((B2-Settings!$B$2)/7)+1) -> 2 | G2: =IF(F2="","",F2>=Settings!$B$5) -> FALSE | J2: =IF(A2="","",IFERROR(INDEX(Requests!$E$2:$E$301,MATCH(A2,Requests!$A$2:$A$301,0)),FALSE())) -> TRUE | K2: =IF(A2="","",IF(AND(H2="Y",COUNTIFS($C$2:C2,C2,$H$2:H2,"Y")=1),1,0)) -> 0
A3: R014 | B3: 46347.083 | C3: B05 | D3: =IF(A3="","",SUMIFS(Quotes!$E$2:$E$301,Quotes!$B$2:$B$301,A3,Quotes!$C$2:$C$301,C3)) -> 520 | E3: =IF(A3="","",IF(D3<500,25,IF(D3<=1500,75,199))) -> 75 | F3: =IF(B3="","",INT((B3-Settings!$B$2)/7)+1) -> 3 | G3: =IF(F3="","",F3>=Settings!$B$5) -> FALSE | J3: =IF(A3="","",IFERROR(INDEX(Requests!$E$2:$E$301,MATCH(A3,Requests!$A$2:$A$301,0)),FALSE())) -> TRUE | K3: =IF(A3="","",IF(AND(H3="Y",COUNTIFS($C$2:C3,C3,$H$2:H3,"Y")=1),1,0)) -> 0
A4: R017 | B4: 46349.354 | C4: B09 | D4: =IF(A4="","",SUMIFS(Quotes!$E$2:$E$301,Quotes!$B$2:$B$301,A4,Quotes!$C$2:$C$301,C4)) -> 900 | E4: =IF(A4="","",IF(D4<500,25,IF(D4<=1500,75,199))) -> 75 | F4: =IF(B4="","",INT((B4-Settings!$B$2)/7)+1) -> 4 | G4: =IF(F4="","",F4>=Settings!$B$5) -> TRUE | H4: Refused | I4: N | J4: =IF(A4="","",IFERROR(INDEX(Requests!$E$2:$E$301,MATCH(A4,Requests!$A$2:$A$301,0)),FALSE())) -> TRUE | K4: =IF(A4="","",IF(AND(H4="Y",COUNTIFS($C$2:C4,C4,$H$2:H4,"Y")=1),1,0)) -> 0
A5: R018 | B5: 46350.615 | C5: B10 | D5: =IF(A5="","",SUMIFS(Quotes!$E$2:$E$301,Quotes!$B$2:$B$301,A5,Quotes!$C$2:$C$301,C5)) -> 650 | E5: =IF(A5="","",IF(D5<500,25,IF(D5<=1500,75,199))) -> 75 | F5: =IF(B5="","",INT((B5-Settings!$B$2)/7)+1) -> 4 | G5: =IF(F5="","",F5>=Settings!$B$5) -> TRUE | H5: Y | I5: N | J5: =IF(A5="","",IFERROR(INDEX(Requests!$E$2:$E$301,MATCH(A5,Requests!$A$2:$A$301,0)),FALSE())) -> TRUE | K5: =IF(A5="","",IF(AND(H5="Y",COUNTIFS($C$2:C5,C5,$H$2:H5,"Y")=1),1,0)) -> 1
A6: R020 | B6: 46355.208 | C6: B11 | D6: =IF(A6="","",SUMIFS(Quotes!$E$2:$E$301,Quotes!$B$2:$B$301,A6,Quotes!$C$2:$C$301,C6)) -> 250 | E6: =IF(A6="","",IF(D6<500,25,IF(D6<=1500,75,199))) -> 25 | F6: =IF(B6="","",INT((B6-Settings!$B$2)/7)+1) -> 4 | G6: =IF(F6="","",F6>=Settings!$B$5) -> TRUE | J6: =IF(A6="","",IFERROR(INDEX(Requests!$E$2:$E$301,MATCH(A6,Requests!$A$2:$A$301,0)),FALSE())) -> FALSE | K6: =IF(A6="","",IF(AND(H6="Y",COUNTIFS($C$2:C6,C6,$H$2:H6,"Y")=1),1,0)) -> 0
A7: R021 | B7: 46354.469 | C7: B07 | D7: =IF(A7="","",SUMIFS(Quotes!$E$2:$E$301,Quotes!$B$2:$B$301,A7,Quotes!$C$2:$C$301,C7)) -> 150 | E7: =IF(A7="","",IF(D7<500,25,IF(D7<=1500,75,199))) -> 25 | F7: =IF(B7="","",INT((B7-Settings!$B$2)/7)+1) -> 4 | G7: =IF(F7="","",F7>=Settings!$B$5) -> TRUE | H7: Y | I7: N | J7: =IF(A7="","",IFERROR(INDEX(Requests!$E$2:$E$301,MATCH(A7,Requests!$A$2:$A$301,0)),FALSE())) -> TRUE | K7: =IF(A7="","",IF(AND(H7="Y",COUNTIFS($C$2:C7,C7,$H$2:H7,"Y")=1),1,0)) -> 1
A8: R024 | B8: 46359.208 | C8: B05 | D8: =IF(A8="","",SUMIFS(Quotes!$E$2:$E$301,Quotes!$B$2:$B$301,A8,Quotes!$C$2:$C$301,C8)) -> 560 | E8: =IF(A8="","",IF(D8<500,25,IF(D8<=1500,75,199))) -> 75 | F8: =IF(B8="","",INT((B8-Settings!$B$2)/7)+1) -> 5 | G8: =IF(F8="","",F8>=Settings!$B$5) -> TRUE | H8: Y | I8: N | J8: =IF(A8="","",IFERROR(INDEX(Requests!$E$2:$E$301,MATCH(A8,Requests!$A$2:$A$301,0)),FALSE())) -> TRUE | K8: =IF(A8="","",IF(AND(H8="Y",COUNTIFS($C$2:C8,C8,$H$2:H8,"Y")=1),1,0)) -> 1
A9: R028 | B9: 46364.042 | C9: B07 | D9: =IF(A9="","",SUMIFS(Quotes!$E$2:$E$301,Quotes!$B$2:$B$301,A9,Quotes!$C$2:$C$301,C9)) -> 150 | E9: =IF(A9="","",IF(D9<500,25,IF(D9<=1500,75,199))) -> 25 | F9: =IF(B9="","",INT((B9-Settings!$B$2)/7)+1) -> 6 | G9: =IF(F9="","",F9>=Settings!$B$5) -> TRUE | H9: Y | I9: N | J9: =IF(A9="","",IFERROR(INDEX(Requests!$E$2:$E$301,MATCH(A9,Requests!$A$2:$A$301,0)),FALSE())) -> TRUE | K9: =IF(A9="","",IF(AND(H9="Y",COUNTIFS($C$2:C9,C9,$H$2:H9,"Y")=1),1,0)) -> 0
A10: R030 | B10: 46368.198 | C10: B05 | D10: =IF(A10="","",SUMIFS(Quotes!$E$2:$E$301,Quotes!$B$2:$B$301,A10,Quotes!$C$2:$C$301,C10)) -> 560 | E10: =IF(A10="","",IF(D10<500,25,IF(D10<=1500,75,199))) -> 75 | F10: =IF(B10="","",INT((B10-Settings!$B$2)/7)+1) -> 6 | G10: =IF(F10="","",F10>=Settings!$B$5) -> TRUE | H10: Y | I10: N | J10: =IF(A10="","",IFERROR(INDEX(Requests!$E$2:$E$301,MATCH(A10,Requests!$A$2:$A$301,0)),FALSE())) -> TRUE | K10: =IF(A10="","",IF(AND(H10="Y",COUNTIFS($C$2:C10,C10,$H$2:H10,"Y")=1),1,0)) -> 0
D11: =IF(A11="","",SUMIFS(Quotes!$E$2:$E$301,Quotes!$B$2:$B$301,A11,Quotes!$C$2:$C$301,C11)) | E11: =IF(A11="","",IF(D11<500,25,IF(D11<=1500,75,199))) | F11: =IF(B11="","",INT((B11-Settings!$B$2)/7)+1) | G11: =IF(F11="","",F11>=Settings!$B$5) | J11: =IF(A11="","",IFERROR(INDEX(Requests!$E$2:$E$301,MATCH(A11,Requests!$A$2:$A$301,0)),FALSE())) | K11: =IF(A11="","",IF(AND(H11="Y",COUNTIFS($C$2:C11,C11,$H$2:H11,"Y")=1),1,0))
D12: =IF(A12="","",SUMIFS(Quotes!$E$2:$E$301,Quotes!$B$2:$B$301,A12,Quotes!$C$2:$C$301,C12)) | E12: =IF(A12="","",IF(D12<500,25,IF(D12<=1500,75,199))) | F12: =IF(B12="","",INT((B12-Settings!$B$2)/7)+1) | G12: =IF(F12="","",F12>=Settings!$B$5) | J12: =IF(A12="","",IFERROR(INDEX(Requests!$E$2:$E$301,MATCH(A12,Requests!$A$2:$A$301,0)),FALSE())) | K12: =IF(A12="","",IF(AND(H12="Y",COUNTIFS($C$2:C12,C12,$H$2:H12,"Y")=1),1,0))
D13: =IF(A13="","",SUMIFS(Quotes!$E$2:$E$301,Quotes!$B$2:$B$301,A13,Quotes!$C$2:$C$301,C13)) | E13: =IF(A13="","",IF(D13<500,25,IF(D13<=1500,75,199))) | F13: =IF(B13="","",INT((B13-Settings!$B$2)/7)+1) | G13: =IF(F13="","",F13>=Settings!$B$5) | J13: =IF(A13="","",IFERROR(INDEX(Requests!$E$2:$E$301,MATCH(A13,Requests!$A$2:$A$301,0)),FALSE())) | K13: =IF(A13="","",IF(AND(H13="Y",COUNTIFS($C$2:C13,C13,$H$2:H13,"Y")=1),1,0))
D14: =IF(A14="","",SUMIFS(Quotes!$E$2:$E$301,Quotes!$B$2:$B$301,A14,Quotes!$C$2:$C$301,C14)) | E14: =IF(A14="","",IF(D14<500,25,IF(D14<=1500,75,199))) | F14: =IF(B14="","",INT((B14-Settings!$B$2)/7)+1) | G14: =IF(F14="","",F14>=Settings!$B$5) | J14: =IF(A14="","",IFERROR(INDEX(Requests!$E$2:$E$301,MATCH(A14,Requests!$A$2:$A$301,0)),FALSE())) | K14: =IF(A14="","",IF(AND(H14="Y",COUNTIFS($C$2:C14,C14,$H$2:H14,"Y")=1),1,0))
D15: =IF(A15="","",SUMIFS(Quotes!$E$2:$E$301,Quotes!$B$2:$B$301,A15,Quotes!$C$2:$C$301,C15)) | E15: =IF(A15="","",IF(D15<500,25,IF(D15<=1500,75,199))) | F15: =IF(B15="","",INT((B15-Settings!$B$2)/7)+1) | G15: =IF(F15="","",F15>=Settings!$B$5) | J15: =IF(A15="","",IFERROR(INDEX(Requests!$E$2:$E$301,MATCH(A15,Requests!$A$2:$A$301,0)),FALSE())) | K15: =IF(A15="","",IF(AND(H15="Y",COUNTIFS($C$2:C15,C15,$H$2:H15,"Y")=1),1,0))
D16: =IF(A16="","",SUMIFS(Quotes!$E$2:$E$301,Quotes!$B$2:$B$301,A16,Quotes!$C$2:$C$301,C16)) | E16: =IF(A16="","",IF(D16<500,25,IF(D16<=1500,75,199))) | F16: =IF(B16="","",INT((B16-Settings!$B$2)/7)+1) | G16: =IF(F16="","",F16>=Settings!$B$5) | J16: =IF(A16="","",IFERROR(INDEX(Requests!$E$2:$E$301,MATCH(A16,Requests!$A$2:$A$301,0)),FALSE())) | K16: =IF(A16="","",IF(AND(H16="Y",COUNTIFS($C$2:C16,C16,$H$2:H16,"Y")=1),1,0))
D17: =IF(A17="","",SUMIFS(Quotes!$E$2:$E$301,Quotes!$B$2:$B$301,A17,Quotes!$C$2:$C$301,C17)) | E17: =IF(A17="","",IF(D17<500,25,IF(D17<=1500,75,199))) | F17: =IF(B17="","",INT((B17-Settings!$B$2)/7)+1) | G17: =IF(F17="","",F17>=Settings!$B$5) | J17: =IF(A17="","",IFERROR(INDEX(Requests!$E$2:$E$301,MATCH(A17,Requests!$A$2:$A$301,0)),FALSE())) | K17: =IF(A17="","",IF(AND(H17="Y",COUNTIFS($C$2:C17,C17,$H$2:H17,"Y")=1),1,0))
D18: =IF(A18="","",SUMIFS(Quotes!$E$2:$E$301,Quotes!$B$2:$B$301,A18,Quotes!$C$2:$C$301,C18)) | E18: =IF(A18="","",IF(D18<500,25,IF(D18<=1500,75,199))) | F18: =IF(B18="","",INT((B18-Settings!$B$2)/7)+1) | G18: =IF(F18="","",F18>=Settings!$B$5) | J18: =IF(A18="","",IFERROR(INDEX(Requests!$E$2:$E$301,MATCH(A18,Requests!$A$2:$A$301,0)),FALSE())) | K18: =IF(A18="","",IF(AND(H18="Y",COUNTIFS($C$2:C18,C18,$H$2:H18,"Y")=1),1,0))
D19: =IF(A19="","",SUMIFS(Quotes!$E$2:$E$301,Quotes!$B$2:$B$301,A19,Quotes!$C$2:$C$301,C19)) | E19: =IF(A19="","",IF(D19<500,25,IF(D19<=1500,75,199))) | F19: =IF(B19="","",INT((B19-Settings!$B$2)/7)+1) | G19: =IF(F19="","",F19>=Settings!$B$5) | J19: =IF(A19="","",IFERROR(INDEX(Requests!$E$2:$E$301,MATCH(A19,Requests!$A$2:$A$301,0)),FALSE())) | K19: =IF(A19="","",IF(AND(H19="Y",COUNTIFS($C$2:C19,C19,$H$2:H19,"Y")=1),1,0))
D20: =IF(A20="","",SUMIFS(Quotes!$E$2:$E$301,Quotes!$B$2:$B$301,A20,Quotes!$C$2:$C$301,C20)) | E20: =IF(A20="","",IF(D20<500,25,IF(D20<=1500,75,199))) | F20: =IF(B20="","",INT((B20-Settings!$B$2)/7)+1) | G20: =IF(F20="","",F20>=Settings!$B$5) | J20: =IF(A20="","",IFERROR(INDEX(Requests!$E$2:$E$301,MATCH(A20,Requests!$A$2:$A$301,0)),FALSE())) | K20: =IF(A20="","",IF(AND(H20="Y",COUNTIFS($C$2:C20,C20,$H$2:H20,"Y")=1),1,0))
D21: =IF(A21="","",SUMIFS(Quotes!$E$2:$E$301,Quotes!$B$2:$B$301,A21,Quotes!$C$2:$C$301,C21)) | E21: =IF(A21="","",IF(D21<500,25,IF(D21<=1500,75,199))) | F21: =IF(B21="","",INT((B21-Settings!$B$2)/7)+1) | G21: =IF(F21="","",F21>=Settings!$B$5) | J21: =IF(A21="","",IFERROR(INDEX(Requests!$E$2:$E$301,MATCH(A21,Requests!$A$2:$A$301,0)),FALSE())) | K21: =IF(A21="","",IF(AND(H21="Y",COUNTIFS($C$2:C21,C21,$H$2:H21,"Y")=1),1,0))
D22: =IF(A22="","",SUMIFS(Quotes!$E$2:$E$301,Quotes!$B$2:$B$301,A22,Quotes!$C$2:$C$301,C22)) | E22: =IF(A22="","",IF(D22<500,25,IF(D22<=1500,75,199))) | F22: =IF(B22="","",INT((B22-Settings!$B$2)/7)+1) | G22: =IF(F22="","",F22>=Settings!$B$5) | J22: =IF(A22="","",IFERROR(INDEX(Requests!$E$2:$E$301,MATCH(A22,Requests!$A$2:$A$301,0)),FALSE())) | K22: =IF(A22="","",IF(AND(H22="Y",COUNTIFS($C$2:C22,C22,$H$2:H22,"Y")=1),1,0))
... D301: =IF(A301="","",SUMIFS(Quotes!$E$2:$E$301,Quotes!$B$2:$B$301,A301,Quotes!$C$2:$C$301,C301)) | E301: =IF(A301="","",IF(D301<500,25,IF(D301<=1500,75,199))) | F301: =IF(B301="","",INT((B301-Settings!$B$2)/7)+1) | G301: =IF(F301="","",F301>=Settings!$B$5) | J301: =IF(A301="","",IFERROR(INDEX(Requests!$E$2:$E$301,MATCH(A301,Requests!$A$2:$A$301,0)),FALSE())) | K301: =IF(A301="","",IF(AND(H301="Y",COUNTIFS($C$2:C301,C301,$H$2:H301,"Y")=1),1,0))

Sheet Nudges
A1: Date | B1: Week | C1: Request or business ID | D1: What you did | F1: FAKE TEST DATA in every row. Clear before the real test (Read me).
A2: 46330 | B2: =IF(A2="","",INT((A2-Settings!$B$2)/7)+1) -> 1 | C2: R002 | D2: Reminded a business to quote
A3: 46331 | B3: =IF(A3="","",INT((A3-Settings!$B$2)/7)+1) -> 1 | C3: R003 | D3: Reminded a business to quote
A4: 46336 | B4: =IF(A4="","",INT((A4-Settings!$B$2)/7)+1) -> 2 | C4: R007 | D4: Reminded a business to quote
A5: 46339 | B5: =IF(A5="","",INT((A5-Settings!$B$2)/7)+1) -> 2 | C5: R010 | D5: Reminded a business to quote
A6: 46346 | B6: =IF(A6="","",INT((A6-Settings!$B$2)/7)+1) -> 3 | C6: R015 | D6: Reminded a business to quote
A7: 46348 | B7: =IF(A7="","",INT((A7-Settings!$B$2)/7)+1) -> 3 | C7: R017 | D7: Reminded a business to quote
B8: =IF(A8="","",INT((A8-Settings!$B$2)/7)+1)
B9: =IF(A9="","",INT((A9-Settings!$B$2)/7)+1)
B10: =IF(A10="","",INT((A10-Settings!$B$2)/7)+1)
B11: =IF(A11="","",INT((A11-Settings!$B$2)/7)+1)
